Workbook
Name ____: #REF!
Name ______________________________qw1101: #REF!
Name ______________________________qw1102: #REF!
Name ______________________________qw1103: #REF!
Name ______________________________qw1104: #REF!
Name ______________________________qw1201: #REF!
Name ______________________________qw1202: #REF!
Name ______________________________qw1203: #REF!
Name ______________________________qw1204: #REF!
Name ______________________________qw1301: #REF!
Name ______________________________qw1302: #REF!
Name ______________________________qw1303: #REF!
Name ______________________________qw1304: #REF!
Name ______________________________qw1305: #REF!
Name ______________________________qw1306: #REF!
Name ______________________________qw1307: #REF!
Name ______________________________qw1308: #REF!
Name ______________________________qw1411: #REF!
Name ______________________________qw1412: #REF!
Name ______________________________qw1421: #REF!
Name ______________________________qw1422: #REF!
Name ______________________________qw1423: #REF!
Name ______________________________qw1501: #REF!
Name ______________________________qw1502: #REF!
Name ______________________________qw2111: #REF!
Name ______________________________qw2112: #REF!
Name ______________________________qw2113: #REF!
Name ______________________________qw2114: #REF!
Name ______________________________qw2115: #REF!
Name ______________________________qw2116: #REF!
Name ______________________________qw2121: #REF!
Name ______________________________qw2211: #REF!
Name ______________________________qw2221: #REF!
Name ______________________________qw2222: #REF!
Name ______________________________qw2301: #REF!
Name ______________________________qw2302: #REF!
Name ______________________________qw2401: #REF!
Name ______________________________qw2901: #REF!
Name ______________________________qw3101: #REF!
Name ______________________________qw3102: #REF!
Name ______________________________qw3201: #REF!
Name ______________________________qw3301: #REF!
Name ______________________________qw3401: #REF!
Name ______________________________qw3402: #REF!
Name ______________________________qw3403: #REF!
Name ______________________________qw3501: #REF!
Name ______________________________qw3502: #REF!
Name ______________________________qw3801: #REF!
Name ______________________________qw3911: #REF!
Name ______________________________qw3921: #REF!
Name ______________________________qw4111: #REF!
Name ______________________________qw4112: #REF!
Name ______________________________qw4113: #REF!
Name ______________________________qw4114: #REF!
Name ______________________________qw4115: #REF!
Name ______________________________qw4121: #REF!
Name ______________________________qw4122: #REF!
Name ______________________________qw4131: #REF!
Name ______________________________qw4141: #REF!
Name ______________________________qw4211: #REF!

Sheet 125мм 0,68 0,78
H1: Ед.изм | I1: ANFO | J1: EMULS
A2: Сетка | B2: 3.7 | C2: 3.7 | D2: Сетка | E2: 4 | F2: 4 | G2: Объем блока | H2: м3 | I2: =P4 -> 25000 | J2: =Q4 -> 25000 | L2: Смета затрат на производство взрывных работ на объекте
A3: Глубина | B3: 11 | D3: Глубина | E3: 11 | G3: Кол-во скважин | H3: шт. | I3: =I2/B5+5 -> 187.61505 | J3: =J2/E5+5 -> 161.25 | L3: "карьер м-ия С-Саркаевское гор. +150 " ООО "Ергач"
A4: Удельный | B4: =B6/B5 -> 0.68148875 | D4: Удельный | E4: =E6/E5 -> 0.7888984 | G4: Кол-во п.м. | H4: п.м. | I4: =I3*A8 -> 2063.7655 | J4: =J3*D8 -> 1773.75 | L4: Средний объем взрываемого блока, м3 | P4: 25000 | Q4: 25000
A5: Выход | B5: =B2*C2*(B3-$I$13) -> 136.9 | D5: Выход | E5: =E2*F2*(E3-$I$13) -> 160 | G5: Масса ВВ | H5: кг. | I5: =I3*B19 -> 17503.698 | J5: =J3*E19 -> 20353.579
A6: Заряд | B6: =B19+B13 -> 93.29581 | D6: Заряд | E6: =E19+E13 -> 126.22374 | G6: Шашка ДПУ-ПТ600 | H6: шт. | I6: =I3+4 -> 191.61505 | J6: =J3+4 -> 165.25 | L6: Выход В.Г.М. с 1 сважины,м3 | P6: =B5 -> 136.9 | Q6: =E5 -> 160
H7: кг. | I7: =I6*0.65 -> 124.54978 | J7: =J6*0.65 -> 107.4125 | L7: Кол-во скважин, шт | P7: =I3 -> 187.61505 | Q7: =J3 -> 161.25
A8: =B3 -> 11 | C8: =A32*22 -> 2.8875 | D8: =E3 -> 11 | F8: =A32*22 -> 2.8875 | G8: С-500-15 | H8: шт. | I8: =I6 -> 191.61505 | J8: =J6 -> 165.25 | L8: Выход В.Г.М. с 1 п.м. скважины | P8: =B5/B3 -> 12.445455 | Q8: =E5/E3 -> 14.545455
G9: П-17-5 | H9: шт. | I9: =I3/10+2 -> 20.761505 | J9: =J3/10+2 -> 18.125 | L9: Объем буровых работ, м | P9: =I4 -> 2063.7655 | Q9: =J4 -> 1773.75
G10: П-25-5 | H10: шт. | I10: =I3+2 -> 189.61505 | J10: =J3+2 -> 163.25 | L10: Удельный расход с учетом парносближенных | P10: =I5/I2 -> 0.70014792 | Q10: =J5/J2 -> 0.81414314
G11: ЭД-8М1 | H11: шт. | I11: 2 | J11: 2 | L11: Количество смен бурения | P11: =P9/I16+I24 -> 21.637655 | Q11: =Q9/J16+J24 -> 18.7375
P12: БВР сухие | Q12: БВР обв | R12: ВР сухие | S12: ВР обв | T12: Бурение
G13: Перебур | H13: м | I13: 1 | J13: 1 | L13: Материалы: | M13: Ед. изм. | N13: Кол-во | O13: Цена | P13: Сумма | Q13: Сумма | T13: Сумма
G14: Продолж-ть смены | H14: ч | I14: 10 | J14: 10 | L14: Аммиачная селитра пористая | O14: =[316]Лист1!$D$2 -> #REF! | P14: =N14*O14 -> #REF!
G15: Скорость проходки | H15: п.м./ч | I15: 10 | J15: 10 | L15: Дизельное топливо | O15: =[317]Лист1!$D$4 -> #REF! | P15: =N15*O15 -> #REF!
G16: Произв-ть смены | H16: п.м./см | I16: =I14*I15 -> 100 | J16: =J14*J15 -> 100 | L16: ПВВ "Гранулит АСП" | M16: т | N16: =P4*P10/1000 -> 17.503698 | O16: ='[318]Гранулит АСП-1'!$I$21 -> #REF! | P16: =N16*O16 -> #REF! | R16: =P16 -> #REF!
G17: Коэф-т исп-я обсадных | H17: % | I17: 0.1 | J17: 0.1 | L17: ЭВВ "Березит" | M17: т | N17: =Q4*Q10/1000 -> 20.353579 | O17: ='[319]Березит Э-100'!$P$50 -> #REF! | Q17: =N17*O17 -> #REF! | S17: =Q17 -> #REF!
G18: Норм. прох-ки коронки | H18: п.м. | I18: 700 | J18: 700 | L18: =[320]Лист1!$B$4 -> #REF! | M18: т | N18: =I7/1000 -> 0.12454978 | O18: =[320]Лист1!$E$4 -> #REF! | Q18: =J7/1000*O18 -> #REF! | S18: =Q18 -> #REF!
B19: =C19*D32 -> 93.29581 | C19: =A8-C8-C13-C16 -> 8.1125 | E19: =F19*D34 -> 126.22374 | F19: =D8-F8-F13-F16 -> 8.1125 | G19: Норм. прох-ки ППУ | H19: п.м. | I19: 10000 | J19: 10000 | L19: =[320]Лист1!$B$5 -> #REF! | M19: т | N19: =(I6+5)*0.0004 -> 0.078646019 | O19: =[320]Лист1!$E$5 -> #REF! | P19: =N19*O19 -> #REF! | R19: =P19 -> #REF!
G20: Норм. проходки РК | H20: п.м. | I20: 15000 | J20: 15000 | L20: =[320]Лист1!$B$7 -> #REF! | M20: шт | N20: =I8 -> 191.61505 | O20: =[320]Лист1!$F$7 -> #REF! | P20: =I8*O20 -> #REF! | Q20: =J8*O20 -> #REF! | R20: =P20 -> #REF! | S20: =Q20 -> #REF!
B21: АСП | G21: Норм. проходки штанга | H21: п.м. | I21: 10000 | J21: 10000 | L21: =[320]Лист1!$B$11 -> #REF! | M21: шт | N21: =I9 -> 20.761505 | O21: =[320]Лист1!$F$11 -> #REF! | P21: =I9*O21 -> #REF! | Q21: =J9*O21 -> #REF! | R21: =P21 -> #REF! | S21: =Q21 -> #REF!
E22: ЭВВ | L22: =[320]Лист1!$B$11 -> #REF! | M22: шт | N22: =I10 -> 189.61505 | O22: =[320]Лист1!$F$11 -> #REF! | P22: =I10*O22 -> #REF! | Q22: =J10*O22 -> #REF! | R22: =P22 -> #REF! | S22: =Q22 -> #REF!
L23: =[320]Лист1!$B$17 -> #REF! | M23: шт | N23: 2 | O23: =[320]Лист1!$D$17 -> #REF! | P23: =I11*O23 -> #REF! | Q23: =J11*O23 -> #REF! | R23: =P23 -> #REF! | S23: =Q23 -> #REF!
G24: Непроизв. работа экипажа БУ | H24: см | I24: 1 | J24: 1 | L24: =[321]Лист1!$B$18 -> #REF! | M24: шт | O24: =[321]Лист1!$D$18 -> #REF!
G25: Стоимость проживания | H25: руб | I25: 1000 | J25: 1000 | L25: ИТОГО ВМ: | P25: =SUM(P16:P23) -> #REF! | Q25: =SUM(Q16:Q23) -> #REF! | R25: =SUM(R16:R23) -> #REF! | S25: =SUM(S16:S23) -> #REF! | T25: =SUM(T16:T23) -> 0
L26: Хранение, производство и доставка ВМ и СИ
L27: Стоимость хранения | M27: руб. | P27: =P4*1.5 -> 37500 | Q27: =Q4*1.5 -> 37500 | R27: =P27 -> 37500 | S27: =Q27 -> 37500
L28: Доставка , разгрузка ВМ | M28: руб. | P28: 5000 | Q28: 5000 | R28: =P28 -> 5000 | S28: =Q28 -> 5000
L29: Энергозатраты на производство ЭВВ Березит | M29: руб. | N29: =N17 -> 20.353579 | O29: ='[322]Березит Э-100'!$E$73 -> #REF! | Q29: =N29*O29 -> #REF! | S29: =Q29 -> #REF!
A30: Диаметр заряда, м | D30: Вместимость, кг | L30: Разгрузка, перевалка компонентов | M30: руб. | N30: =N16 -> 17.503698 | O30: 700 | P30: =N30*O30 -> 12252.589 | Q30: =N17*O30 -> 14247.505 | R30: =P30 -> 12252.589 | S30: =Q30 -> 14247.505
D31: ANFO | L31: Роялти
A32: 0.13125 | D32: =PI()*POWER(A32,2)/4*850 -> 11.500254 | L32: Итого расходы на хранение и доставку | P32: =SUM(P27:P30) -> 54752.589 | Q32: =SUM(Q27:Q30) -> #REF! | R32: =SUM(R27:R30) -> 54752.589 | S32: =SUM(S27:S30) -> #REF! | T32: =SUM(T27:T30) -> 0
D33: EMULS | L33: Буровой инструмент: | P33: =N34*O34+N35*O35+N36*O36+N37*O37+N38*O38+N39*O39+N40*O40+N41*O41 -> #REF!
D34: =PI()*POWER(A32,2)/4*1150 -> 15.559167 | L34: =[323]Лист1!$B$17 -> #REF! | M34: шт | N34: =P9/I18 -> 2.9482365 | O34: =[323]Лист1!$D$17*1.2 -> #REF! | P34: =P4/P8/I18*O34 -> #REF! | Q34: =Q4/Q8/J18*O34 -> #REF! | T34: =O34/I18 -> #REF!
L35: =[323]Лист1!$B$5 -> #REF! | M35: шт | N35: =P9/I19 -> 0.20637655 | O35: =[323]Лист1!$D$5 -> #REF! | P35: =P4/P8/I19*O35 -> #REF! | Q35: =Q4/Q8/J19*O35 -> #REF! | T35: =O35/I19 -> #REF!
L36: =[323]Лист1!$B$24 -> #REF! | M36: шт | N36: =P9/I20 -> 0.13758437 | O36: =[323]Лист1!$D$24 -> #REF! | P36: =P4/P8/I20*O36 -> #REF! | Q36: =Q4/Q8/J20*P36 -> #REF! | T36: =O36/I20 -> #REF!
L37: =[323]Лист1!$B$27 -> #REF! | M37: шт | N37: =P9/6000 -> 0.34396092 | O37: =[323]Лист1!$D$27 -> #REF! | P37: =N37*O37 -> #REF! | T37: =O37/10000 -> #REF!
L38: =[323]Лист1!$B$42 -> #REF! | M38: шт | N38: =P9/I21 -> 0.20637655 | O38: =[323]Лист1!$D$42 -> #REF! | P38: =P4/P8/I21*O38 -> #REF! | Q38: =Q4/Q8/J21*O38 -> #REF! | T38: =O38/J21 -> #REF!
L39: =[324]Лист1!$B$51 -> #REF! | M39: шт | N39: 0.5 | O39: =[324]Лист1!$D$51*1.21 -> #REF! | P39: =N39*O39 -> #REF!
L40: =[323]Лист1!$B$60 -> #REF! | M40: п.м. | N40: =P9*I17 -> 206.37655 | O40: =[323]Лист1!$D$60 -> #REF! | P40: =N40*O40 -> #REF! | Q40: =Q9*J17*O40 -> #REF! | T40: =O40*0.1 -> #REF!
...

Sheet Лист3
A1: Гранулит АСП-1
A2: Березит Э-100 Рецептура № 1

Sheet смета расч. 0,88 1,16 D165
A1: Исходные данные, технические параметры для расчета | Q1: Смета затрат | W1: =#REF! -> #REF! | AA1: проверка расчетов | AC1: =(S7+T7+U7+V7+W7)-S8-T8-U8-V8-W8-W17-V17-U17-T17-S17+S26+T26+U26+V26+W26-S27-S33-S37-S48-S54-S60-T27-T33-T37-T48-T54-T60-U60-U54-U48-U37-U33-U27-V27-V33-V37-V48-V54-V60-W60-W54-W48-W37-W33-W27 -> #VALUE! | AE1: если не 0- ищем ошибку
Q2: на производство взрывных работ на объекте | T2: поставка вм | AC2: =S7+S26-S67+T7+T26-T67+U7+U26-U67+V7+V26-V67+W7+W26-W67 -> #VALUE!
H3: Показатель | I3: Ед.изм | J3: ANFO | K3: EMULS | Q3: "карьер м-ия Ломовское" АО "ТК" | W3: пм
A4: Сетка | B4: 4 | C4: 4 | D4: Сетка | E4: 4 | F4: 4.2 | H4: Объем блока | I4: м3 | J4: =S5 -> 20000 | K4: =T5 -> 20000 | R4: базовый тариф
A5: Глубина | B5: 11.5 | D5: Глубина | E5: 11.5 | H5: Кол-во скважин | I5: шт. | J5: =J4/B7 -> 119.04762 | K5: =K4/E7 -> 113.37868 | N5: К потерь | O5: 1 | R5: Объем справочно, м3 | S5: 20000 | T5: =S5 -> 20000 | U5: =S5 -> 20000 | V5: =T5 -> 20000 | W5: 10000
A6: Удельный | B6: =B8/B7 -> 0.82964053 | D6: Удельный | E6: =E8/E7 -> 1.0817308 | H6: Добавочные скважины | J6: 7 | K6: 7 | M6: № п/п | N6: Наименование | O6: Ед. изм. | P6: Норма const ANFO (кг./л.//1000 м3) | Q6: Норма const EMULS (кг./л.//1000 м3) | R6: Цена (руб./шт, тн) | S6: БВР сухие | T6: БВР обв | U6: ВР сухие | V6: ВР обв | W6: Бурение
A7: Выход | B7: =B4*C4*(B5-$J$18) -> 168 | D7: Выход | E7: =E4*F4*(E5-$J$18) -> 176.4 | H7: Кол-во п.м. | I7: п.м. | J7: =(J5+J6)*A10 -> 1449.5476 | K7: =(K5+K6)*D10 -> 1384.3549 | M7: 1 | N7: Переменные расходы | S7: =SUBTOTAL(9,S9:S25) -> #VALUE! | T7: =SUBTOTAL(9,T9:T25) -> #VALUE! | U7: =SUBTOTAL(9,U9:U25) -> #VALUE! | V7: =SUBTOTAL(9,V9:V25) -> #VALUE! | W7: =SUBTOTAL(9,W8:W17) -> 0
A8: Заряд | B8: =B21+B15 -> 139.37961 | D8: Заряд | E8: =E21+E15 -> 190.81732 | H8: Масса ВВ | I8: кг. | J8: =(J5+J6)*B21 -> 17568.468 | K8: =(K5+K6)*E21 -> 22970.338 | M8: 1.1. | N8: Расходы на ВМ | S8: =SUBTOTAL(9,S9:S16) -> #VALUE! | T8: =SUBTOTAL(9,T9:T16) -> #VALUE! | U8: =SUBTOTAL(9,U9:U16) -> #VALUE! | V8: =SUBTOTAL(9,V9:V16) -> #VALUE! | W8: =SUBTOTAL(9,W9:W16) -> 0
H9: Шашка ДПУ-ПТ600 | I9: шт. | J9: =J5+J6+4 -> 130.04762 | K9: =K5+K6+4 -> 124.37868 | N9: Гранулит АСП-1 | O9: тн | P9: =J32 -> 0.87842339 | Q9: 0 | R9: =VLOOKUP(N9,#REF!,16,0) -> #REF! | S9: =IF(ISERR($P$9*$R$9)," ",($P$9*$R$9))/1000*$S$5 -> #VALUE! | T9: =IF(ISERR($Q$9*$R$9)," ",($Q$9*$R$9))/1000*$T$5 -> #VALUE! | U9: =IF(ISERR($P$9*$R$9)," ",($P$9*$R$9))/1000*$U$5 -> #VALUE! | V9: =IF(ISERR($Q$9*$R$9)," ",($Q$9*$R$9))/1000*$V$5 -> #VALUE!
A10: =B5 -> 11.5 | C10: =A34*25 -> 4.275 | D10: =E5 -> 11.5 | F10: =A34*25 -> 4.275 | H10: Шашка ДПУ-ПТ600 | I10: кг. | J10: =J9*0.65 -> 84.530952 | K10: =K9*0.65 -> 80.846145 | N10: Березит Э-100 Рецептура № 1 | O10: тн | P10: 0 | Q10: =K32 -> 1.1485169 | R10: =VLOOKUP(N10,#REF!,16,0) -> #REF! | S10: =IF(ISERR($P$10*$R$10)," ",($P$10*$R$10))/1000*$S$5 -> #VALUE! | T10: =IF(ISERR($Q$10*$R$10)," ",($Q$10*$R$10))/1000*$T$5 -> #VALUE! | U10: =IF(ISERR($P$10*$R$10)," ",($P$10*$R$10))/1000*$U$5 -> #VALUE! | V10: =IF(ISERR($Q$10*$R$10)," ",($Q$10*$R$10))/1000*$V$5 -> #VALUE!
H11: Аммонит № 6ЖВ-200 | I11: шт. | J11: =J9 -> 130.04762 | K11: =K9 -> 124.37868 | N11: Детонатор промежуточный ДПУ-ПТ600 | O11: =VLOOKUP(N11,#REF!,2,FALSE) -> #REF! | P11: 0 | Q11: =K10/1000 -> 0.080846145 | R11: =VLOOKUP(N11,#REF!,15,0) -> #REF! | S11: =IF(ISERR($P$11*$R$11)," ",($P$11*$R$11)) | T11: =IF(ISERR($Q$11*$R$11)," ",($Q$11*$R$11)) | U11: =IF(ISERR($P$11*$R$11)," ",($P$11*$R$11)) | V11: =IF(ISERR($Q$11*$R$11)," ",($Q$11*$R$11))
H12: Аммонит № 6ЖВ-200 | I12: кг. | J12: =J11*0.4 -> 52.019048 | K12: =K11*0.4 -> 49.751474 | N12: Аммонит № 6ЖВ-200 ГОСТ 21984-76 | O12: =VLOOKUP(N12,#REF!,2,FALSE) -> #REF! | P12: =J12/1000 -> 0.052019048 | Q12: 0 | R12: =VLOOKUP(N12,#REF!,15,0) -> #REF! | S12: =IF(ISERR($P$12*$R$12)," ",($P$12*$R$12)) | T12: =IF(ISERR($Q$12*$R$12)," ",($Q$12*$R$12)) | U12: =IF(ISERR($P$12*$R$12)," ",($P$12*$R$12)) | V12: =IF(ISERR($Q$12*$R$12)," ",($Q$12*$R$12))
H13: С-500-15 | I13: шт. | J13: =J9 -> 130.04762 | K13: =K9 -> 124.37868 | N13: НСИ "Rionel" серии MS-20-15 м. (в упаковке 1.4 S) | O13: =VLOOKUP(N13,#REF!,2,FALSE) -> #REF! | P13: =J13 -> 130.04762 | Q13: =K13 -> 124.37868 | R13: =VLOOKUP(N13,#REF!,15,0) -> #REF! | S13: =IF(ISERR($P$13*$R$13)," ",($P$13*$R$13)) | T13: =IF(ISERR($Q$13*$R$13)," ",($Q$13*$R$13)) | U13: =IF(ISERR($P$13*$R$13)," ",($P$13*$R$13)) | V13: =IF(ISERR($Q$13*$R$13)," ",($Q$13*$R$13))
H14: П-17-5 | I14: шт. | J14: =(J5+J6)/10+2 -> 14.604762 | K14: =(K5+K6)/10+2 -> 14.037868 | N14: НСИ "Rionel" серии Х-*-4,2 м. (в упаковке 1.4 S) | O14: =VLOOKUP(N14,#REF!,2,FALSE) -> #REF! | P14: =J14 -> 14.604762 | Q14: =K14 -> 14.037868 | R14: =VLOOKUP(N14,#REF!,15,0) -> #REF! | S14: =IF(ISERR($P$14*$R$14)," ",($P$14*$R$14)) | T14: =IF(ISERR($Q$14*$R$14)," ",($Q$14*$R$14)) | U14: =IF(ISERR($P$14*$R$14)," ",($P$14*$R$14)) | V14: =IF(ISERR($Q$14*$R$14)," ",($Q$14*$R$14))
H15: П-25-5 | I15: шт. | J15: =J5+J6+2 -> 128.04762 | K15: =K5+K6+2 -> 122.37868 | N15: НСИ "Rionel" серии Х-*-4,2 м. (в упаковке 1.4 S) | O15: =VLOOKUP(N15,#REF!,2,FALSE) -> #REF! | P15: =J15 -> 128.04762 | Q15: =K15 -> 122.37868 | R15: =VLOOKUP(N15,#REF!,15,0) -> #REF! | S15: =IF(ISERR($P$15*$R$15)," ",($P$15*$R$15)) | T15: =IF(ISERR($Q$15*$R$15)," ",($Q$15*$R$15)) | U15: =IF(ISERR($P$15*$R$15)," ",($P$15*$R$15)) | V15: =IF(ISERR($Q$15*$R$15)," ",($Q$15*$R$15))
H16: ЭД-8М1 | I16: шт. | J16: 2 | K16: 2 | N16: Электродетонатор ЭД-8М1 | O16: =VLOOKUP(N16,#REF!,2,FALSE) -> #REF! | P16: =J16 -> 2 | Q16: =K16 -> 2 | R16: =VLOOKUP(N16,#REF!,15,0) -> #REF! | S16: =IF(ISERR($P$16*$R$16)," ",($P$16*$R$16)) | T16: =IF(ISERR($Q$16*$R$16)," ",($Q$16*$R$16)) | U16: =IF(ISERR($P$16*$R$16)," ",($P$16*$R$16)) | V16: =IF(ISERR($Q$16*$R$16)," ",($Q$16*$R$16))
M17: 1.2. | N17: Расходы на буровой инструмент | S17: =SUBTOTAL(9,S18:S25) -> 1100 | T17: =SUBTOTAL(9,T18:T25) -> 1100 | U17: =SUBTOTAL(9,U18:U25) -> 0 | V17: =SUBTOTAL(9,V18:V25) -> 0 | W17: =SUBTOTAL(9,W18:W25) -> 0
H18: Перебур | I18: м | J18: 1 | K18: 1 | N18: Пневмоударник DT-H4 DHD340 2-3/8 API Reg | O18: =VLOOKUP(N18,#REF!,2,FALSE) -> #REF! | P18: =J7/J24 -> 0.14495476 | Q18: =K7/K24 -> 0.13843549 | R18: =VLOOKUP(N18,#REF!,15,0) -> #REF! | S18: =IF(ISERR($P$18*$R$18)," ",($P$18*$R$18)) | T18: =IF(ISERR($Q$18*$R$18)," ",($Q$18*$R$18))
H19: Продолж-ть смены | I19: ч | J19: 10 | K19: 10 | N19: Ремкомплект DT-H4 DHD340 (внешний) | O19: =VLOOKUP(N19,#REF!,2,FALSE) -> #REF! | P19: =J7/J25 -> 0.20707823 | Q19: =K7/K25 -> 0.19776498 | R19: =VLOOKUP(N19,#REF!,15,0) -> #REF! | S19: =IF(ISERR($P$19*$R$19)," ",($P$19*$R$19)) | T19: =IF(ISERR($Q$19*$R$19)," ",($Q$19*$R$19))
H20: Скорость проходки | I20: п.м./ч | J20: 14 | K20: 14 | N20: Труба буровая ТБСУ 63,5х6,0х4700 мм | O20: =VLOOKUP(N20,#REF!,2,FALSE) -> #REF! | P20: =J7/J27 -> 0.28990952 | Q20: =K7/K27 -> 0.27687098 | R20: =VLOOKUP(N20,#REF!,15,0) -> #REF! | S20: =IF(ISERR($P$20*$R$20)," ",($P$20*$R$20)) | T20: =IF(ISERR($Q$20*$R$20)," ",($Q$20*$R$20))
B21: =C21*D34 -> 139.37961 | C21: =A10-C10-C15-C18 -> 7.225 | E21: =F21*D36 -> 190.81732 | F21: =D10-F10-F15-F18 -> 7.225 | H21: Произв-ть смены | I21: п.м./см | J21: =J19*J20 -> 140 | K21: =K19*K20 -> 140 | N21: Переводник З-50/З-66м(2паза) | O21: =VLOOKUP(N21,#REF!,2,FALSE) -> #REF! | P21: =J7/10000 -> 0.14495476 | Q21: =K7/10000 -> 0.13843549 | R21: =VLOOKUP(N21,#REF!,15,0) -> #REF! | S21: =IF(ISERR($P$21*$R$21)," ",($P$21*$R$21)) | T21: =IF(ISERR($Q$21*$R$21)," ",($Q$21*$R$21))
H22: Коэф-т исп-я обсадных | I22: % | J22: 0.1 | K22: 0.1 | N22: Труба техническая D125 SDR 26 ТУ 2248-001-49127551-2014 | O22: п.м. | P22: =J7*J22 -> 144.95476 | Q22: =K7*K22 -> 138.43549 | R22: =VLOOKUP(N22,#REF!,15,0) -> #REF! | S22: =IF(ISERR($P$22*$R$22)," ",($P$22*$R$22)) | T22: =IF(ISERR($Q$22*$R$22)," ",($Q$22*$R$22))
B23: АСП | H23: Норм. прох-ки коронки | I23: п.м. | J23: 700 | K23: 700 | N23: Коронка буровая DT-DHD340 125 мм CVD/SBL | O23: =VLOOKUP(N23,#REF!,2,FALSE) -> #REF! | P23: =J7/J23 -> 2.0707823 | Q23: =K7/K23 -> 1.9776498 | R23: =VLOOKUP(N23,#REF!,15,0) -> #REF! | S23: =IF(ISERR($P$23*$R$23)," ",($P$23*$R$23)) | T23: =IF(ISERR($Q$23*$R$23)," ",($Q$23*$R$23))
E24: ЭВВ | H24: Норм. прох-ки ППУ | I24: п.м. | J24: 10000 | K24: 10000
H25: Норм. проходки РК | I25: п.м. | J25: 7000 | K25: 7000 | N25: Доставка инструмента | O25: шт | P25: 0.5 | Q25: 0.5 | R25: 2200 | S25: =IF(ISERR($P$25*$R$25)," ",($P$25*$R$25)) -> 1100 | T25: =IF(ISERR($Q$25*$R$25)," ",($Q$25*$R$25)) -> 1100
M26: 2 | N26: Постоянные расходы | S26: =SUBTOTAL(9,S28:S66) -> #REF! | T26: =SUBTOTAL(9,T28:T66) -> #REF! | U26: =SUBTOTAL(9,U28:U66) -> #REF! | V26: =SUBTOTAL(9,V28:V66) -> #REF! | W26: =SUBTOTAL(9,W28:W60) -> 0
H27: Норм. проходки штанга | I27: п.м. | J27: 5000 | K27: 5000 | M27: 2.1. | N27: Хранение, производство и доставка ВМ и СИ | S27: =SUBTOTAL(9,S28:S32) -> 47297.927 | T27: =SUBTOTAL(9,T28:T32) -> 92922.005 | U27: =SUBTOTAL(9,U28:U32) -> 47297.927 | V27: =SUBTOTAL(9,V28:V32) -> 92922.005 | W27: =SUBTOTAL(9,W28:W32) -> 0
H28: Непроизв. работа экипажа БУ | I28: см | J28: 1 | K28: 1 | N28: Стоимость хранения | S28: =S5*1.5 -> 30000 | T28: =T5*1.5 -> 30000 | U28: =U5*1.5 -> 30000 | V28: =V5*1.5 -> 30000
H29: Стоимость проживания | I29: руб | J29: 500 | K29: 500 | N29: Доставка , разгрузка ВМ | S29: 5000 | T29: 5000 | U29: 5000 | V29: 5000
H30: Выход ВГМ с 1 п.м. скважины | I30: м3 | J30: =B7/B5 -> 14.608696 | K30: =E7/E5 -> 15.33913 | N30: Энергозатраты на производство ЭВВ Березит | Q30: =Q10 -> 1.1485169 | R30: =$K$40 -> 1821.6 | T30: =K8/1000*R30 -> 41842.768 | V30: =K8/1000*R30 -> 41842.768
H31: Выход ВГМ с 1 п.м. с учетом доп. скв | I31: м3 | J31: =J4/J7 -> 13.797408 | K31: =K4/K7 -> 14.447163 | N31: Разгрузка, перевалка компонентов | P31: =P9 -> 0.87842339 | Q31: =Q10 -> 1.1485169 | R31: 700 | S31: =J8/1000*R31 -> 12297.927 | T31: =K8/1000*R31 -> 16079.237 | U31: =J8/1000*R31 -> 12297.927 | V31: =K8/1000*R31 -> 16079.237
A32: Диаметр заряда, м | D32: Вместимость, кг | H32: Удельный расход с учетом парносближенных | J32: =J8/J4 -> 0.87842339 | K32: =K8/K4 -> 1.1485169 | N32: Роялти
D33: ANFO | H33: Количество смен бурения | I33: см | J33: =J7/J21+J28 -> 11.353912 | K33: =K7/K21+K28 -> 10.888249 | M33: 2.2. | N33: Суточные, вахтовые, проживание | O33: чел | P33: кол-во см.бур. | S33: =SUBTOTAL(9,S34:S36) -> 30578.605 | T33: =SUBTOTAL(9,T34:T36) -> 35154.148 | U33: =SUBTOTAL(9,U34:U36) -> 5600 | V33: =SUBTOTAL(9,V34:V36) -> 11200 | W33: =SUBTOTAL(9,W34:W36) -> 0
A34: 0.171 | D34: =PI()*POWER(A34,2)/4*840 -> 19.291295 | H34: Количество смен заряжания | I34: см | J34: 1 | K34: 2 | N34: Суточные (хчел.*700 руб*х дней) | O34: 4 | R34: 700 | S34: =O34*J34*R34 -> 2800 | T34: =O34*K34*R34 -> 5600 | U34: =S34 -> 2800 | V34: =T34 -> 5600
D35: EMULS | N35: Вахтовые (хчел.*1500 руб*х дней) | O35: 4 | R35: 1500 | S35: =J33*$R$35 -> 17030.867 | T35: =K33*$R$35 -> 16332.374
D36: =PI()*POWER(A34,2)/4*1150 -> 26.410702 | N36: Проживание (хчел.*1000 руб*х дней) | O36: 4 | R36: 700 | S36: =$R$36*(J33+O36) -> 10747.738 | T36: =$R$36*(K33+(K34*O36)) -> 13221.774 | U36: =O36*R36*J34 -> 2800 | V36: =O36*R36*K34 -> 5600
H37: Энергозатраты на тонну ЭМ | M37: 2.3. | N37: Фонд оплаты труда | P37: кол-во чел. | S37: =SUBTOTAL(9,S38:S46) -> 154043.62 | T37: =SUBTOTAL(9,T38:T46) -> 162987.94 | U37: =SUBTOTAL(9,U38:U46) -> 48922.896 | V37: =SUBTOTAL(9,V38:V46) -> 60556.533 | W37: =SUBTOTAL(9,W38:W46) -> 0
H38: Электроэнергия, кВА | I38: 40 | J38: 7.14 | K38: =I38*J38 -> 285.6 | N38: Взрывники | P38: 3 | S38: =(S5*0.2+4500)/0.87*P38 -> 29310.345 | T38: =(T5*0.2+4500)/0.87*P38 -> 29310.345 | U38: =(U5*0.2+4500)/0.87*P38 -> 29310.345 | V38: =(V5*0.2+4500)/0.87*P38 -> 29310.345
H39: Дизельное топливо, л | I39: 32 | J39: 48 | K39: =I39*J39 -> 1536 | N39: Водитель СЗМ | P39: 1 | S39: =(P9*10*300+1500)/0.87 -> 4753.1841 | T39: =(Q10*10*300+3000)/0.87 -> 7408.679 | U39: =(P9*10*300+2500)/0.87 -> 5902.6094 | V39: =(Q10*10*300+3000)/0.87 -> 7408.679
K40: =K38+K39 -> 1821.6 | N40: Зав. складом ВМ | P40: 1 | S40: =30000/0.87/15 -> 2298.8506 | T40: =30000/0.87/10 -> 3448.2759 | U40: =30000/0.87/15 -> 2298.8506 | V40: =30000/0.87/10 -> 3448.2759
...

Sheet смета расч. 0,93 1,2 D165
A1: Исходные данные, технические параметры для расчета | Q1: Смета затрат | W1: =#REF! -> #REF! | AA1: проверка расчетов | AC1: =(S7+T7+U7+V7+W7)-S8-T8-U8-V8-W8-W17-V17-U17-T17-S17+S26+T26+U26+V26+W26-S27-S33-S37-S48-S54-S62-T27-T33-T37-T48-T54-T62-U62-U54-U48-U37-U33-U27-V27-V33-V37-V48-V54-V62-W62-W54-W48-W37-W33-W27 -> #VALUE! | AE1: если не 0- ищем ошибку
Q2: на производство взрывных работ на объекте | T2: поставка вм | AC2: =S7+S26-S69+T7+T26-T69+U7+U26-U69+V7+V26-V69+W7+W26-W69 -> #VALUE!
H3: Показатель | I3: Ед.изм | J3: ANFO | K3: EMULS | Q3: "карьер м-ия Ломовское" АО "ТК" | W3: пм
A4: Сетка | B4: 3.7 | C4: 4 | D4: Сетка | E4: 4 | F4: 4 | H4: Объем блока | I4: м3 | J4: =S5 -> 20000 | K4: =T5 -> 20000 | R4: базовый тариф
A5: Глубина | B5: 11.5 | D5: Глубина | E5: 11.5 | H5: Кол-во скважин | I5: шт. | J5: =J4/B7 -> 128.70013 | K5: =K4/E7 -> 119.04762 | N5: К потерь | O5: 1 | R5: Объем справочно, м3 | S5: 20000 | T5: =S5 -> 20000 | U5: =S5 -> 20000 | V5: =T5 -> 20000 | W5: 10000
A6: Удельный | B6: =B8/B7 -> 0.89690868 | D6: Удельный | E6: =E8/E7 -> 1.1358174 | H6: Добавочные скважины | J6: 7 | K6: 7 | M6: № п/п | N6: Наименование | O6: Ед. изм. | P6: Норма const ANFO (кг./л.//1000 м3) | Q6: Норма const EMULS (кг./л.//1000 м3) | R6: Цена (руб./шт, тн) | S6: БВР сухие | T6: БВР обв | U6: ВР сухие | V6: ВР обв | W6: Бурение
A7: Выход | B7: =B4*C4*(B5-$J$18) -> 155.4 | D7: Выход | E7: =E4*F4*(E5-$J$18) -> 168 | H7: Кол-во п.м. | I7: п.м. | J7: =(J5+J6)*A10 -> 1560.5515 | K7: =(K5+K6)*D10 -> 1449.5476 | M7: 1 | N7: Переменные расходы | S7: =SUBTOTAL(9,S9:S25) -> #VALUE! | T7: =SUBTOTAL(9,T9:T25) -> #VALUE! | U7: =SUBTOTAL(9,U9:U25) -> #VALUE! | V7: =SUBTOTAL(9,V9:V25) -> #VALUE! | W7: =SUBTOTAL(9,W8:W17) -> 0
A8: Заряд | B8: =B21+B15 -> 139.37961 | D8: Заряд | E8: =E21+E15 -> 190.81732 | H8: Масса ВВ | I8: кг. | J8: =(J5+J6)*B21 -> 18913.831 | K8: =(K5+K6)*E21 -> 24052.069 | M8: 1.1. | N8: Расходы на ВМ | S8: =SUBTOTAL(9,S9:S16) -> #VALUE! | T8: =SUBTOTAL(9,T9:T16) -> #VALUE! | U8: =SUBTOTAL(9,U9:U16) -> #VALUE! | V8: =SUBTOTAL(9,V9:V16) -> #VALUE! | W8: =SUBTOTAL(9,W9:W16) -> 0
H9: Шашка ДПУ-ПТ600 | I9: шт. | J9: =J5+J6+4 -> 139.70013 | K9: =K5+K6+4 -> 130.04762 | N9: Гранулит АСП-1 | O9: тн | P9: =J32 -> 0.94569154 | Q9: 0 | R9: =VLOOKUP(N9,#REF!,16,0) -> #REF! | S9: =IF(ISERR($P$9*$R$9)," ",($P$9*$R$9))/1000*$S$5 -> #VALUE! | T9: =IF(ISERR($Q$9*$R$9)," ",($Q$9*$R$9))/1000*$T$5 -> #VALUE! | U9: =IF(ISERR($P$9*$R$9)," ",($P$9*$R$9))/1000*$U$5 -> #VALUE! | V9: =IF(ISERR($Q$9*$R$9)," ",($Q$9*$R$9))/1000*$V$5 -> #VALUE!
A10: =B5 -> 11.5 | C10: =A34*25 -> 4.275 | D10: =E5 -> 11.5 | F10: =A34*25 -> 4.275 | H10: Шашка ДПУ-ПТ600 | I10: кг. | J10: =J9*0.65 -> 90.805084 | K10: =K9*0.65 -> 84.530952 | N10: Березит Э-100 Рецептура № 1 | O10: тн | P10: 0 | Q10: =K32 -> 1.2026034 | R10: =VLOOKUP(N10,#REF!,16,0) -> #REF! | S10: =IF(ISERR($P$10*$R$10)," ",($P$10*$R$10))/1000*$S$5 -> #VALUE! | T10: =IF(ISERR($Q$10*$R$10)," ",($Q$10*$R$10))/1000*$T$5 -> #VALUE! | U10: =IF(ISERR($P$10*$R$10)," ",($P$10*$R$10))/1000*$U$5 -> #VALUE! | V10: =IF(ISERR($Q$10*$R$10)," ",($Q$10*$R$10))/1000*$V$5 -> #VALUE!
H11: Аммонит № 6ЖВ-200 | I11: шт. | J11: =J9 -> 139.70013 | K11: =K9 -> 130.04762 | N11: Детонатор промежуточный ДПУ-ПТ600 | O11: =VLOOKUP(N11,#REF!,2,FALSE) -> #REF! | P11: 0 | Q11: =K10/1000 -> 0.084530952 | R11: =VLOOKUP(N11,#REF!,15,0) -> #REF! | S11: =IF(ISERR($P$11*$R$11)," ",($P$11*$R$11)) | T11: =IF(ISERR($Q$11*$R$11)," ",($Q$11*$R$11)) | U11: =IF(ISERR($P$11*$R$11)," ",($P$11*$R$11)) | V11: =IF(ISERR($Q$11*$R$11)," ",($Q$11*$R$11))
H12: Аммонит № 6ЖВ-200 | I12: кг. | J12: =J11*0.4 -> 55.880051 | K12: =K11*0.4 -> 52.019048 | N12: Аммонит № 6ЖВ-200 ГОСТ 21984-76 | O12: =VLOOKUP(N12,#REF!,2,FALSE) -> #REF! | P12: =J12/1000 -> 0.055880051 | Q12: 0 | R12: =VLOOKUP(N12,#REF!,15,0) -> #REF! | S12: =IF(ISERR($P$12*$R$12)," ",($P$12*$R$12)) | T12: =IF(ISERR($Q$12*$R$12)," ",($Q$12*$R$12)) | U12: =IF(ISERR($P$12*$R$12)," ",($P$12*$R$12)) | V12: =IF(ISERR($Q$12*$R$12)," ",($Q$12*$R$12))
H13: С-500-15 | I13: шт. | J13: =J9 -> 139.70013 | K13: =K9 -> 130.04762 | N13: Hitronic II Standard 12 m | O13: =VLOOKUP(N13,#REF!,2,FALSE) -> #REF! | P13: =J13 -> 139.70013 | Q13: =K13 -> 130.04762 | R13: =VLOOKUP(N13,#REF!,15,0) -> #REF! | S13: =IF(ISERR($P$13*$R$13)," ",($P$13*$R$13)) | T13: =IF(ISERR($Q$13*$R$13)," ",($Q$13*$R$13)) | U13: =IF(ISERR($P$13*$R$13)," ",($P$13*$R$13)) | V13: =IF(ISERR($Q$13*$R$13)," ",($Q$13*$R$13))
H14: П-17-5 | I14: шт. | J14: =(J5+J6)/10+2 -> 15.570013 | K14: =(K5+K6)/10+2 -> 14.604762 | N14: 0 | O14: =VLOOKUP(N14,#REF!,2,FALSE) -> #REF! | P14: =J14 -> 15.570013 | Q14: =K14 -> 14.604762 | R14: =VLOOKUP(N14,#REF!,15,0) -> #REF! | S14: =IF(ISERR($P$14*$R$14)," ",($P$14*$R$14)) | T14: =IF(ISERR($Q$14*$R$14)," ",($Q$14*$R$14)) | U14: =IF(ISERR($P$14*$R$14)," ",($P$14*$R$14)) | V14: =IF(ISERR($Q$14*$R$14)," ",($Q$14*$R$14))
H15: П-25-5 | I15: шт. | J15: =J5+J6+2 -> 137.70013 | K15: =K5+K6+2 -> 128.04762 | N15: Провод медный 2-х жильный диаметром 0,60мм на напряжение 24В | O15: =VLOOKUP(N15,#REF!,2,FALSE) -> #REF! | P15: =J17 -> 558.80051 | Q15: =K17 -> 520.19048 | R15: =VLOOKUP(N15,#REF!,15,0) -> #REF! | S15: =IF(ISERR($P$15*$R$15)," ",($P$15*$R$15)) | T15: =IF(ISERR($Q$15*$R$15)," ",($Q$15*$R$15)) | U15: =IF(ISERR($P$15*$R$15)," ",($P$15*$R$15)) | V15: =IF(ISERR($Q$15*$R$15)," ",($Q$15*$R$15))
H16: ЭД-8М1 | I16: шт. | J16: 2 | K16: 2 | N16: Электродетонатор ЭД-8М1 | O16: =VLOOKUP(N16,#REF!,2,FALSE) -> #REF! | P16: =J16 -> 2 | Q16: =K16 -> 2 | R16: =VLOOKUP(N16,#REF!,15,0) -> #REF! | S16: =IF(ISERR($P$16*$R$16)," ",($P$16*$R$16)) | T16: =IF(ISERR($Q$16*$R$16)," ",($Q$16*$R$16)) | U16: =IF(ISERR($P$16*$R$16)," ",($P$16*$R$16)) | V16: =IF(ISERR($Q$16*$R$16)," ",($Q$16*$R$16))
H17: Провод медный | I17: м | J17: =J13*4 -> 558.80051 | K17: =K13*4 -> 520.19048 | M17: 1.2. | N17: Расходы на буровой инструмент | S17: =SUBTOTAL(9,S18:S25) -> 1100 | T17: =SUBTOTAL(9,T18:T25) -> 1100 | U17: =SUBTOTAL(9,U18:U25) -> 0 | V17: =SUBTOTAL(9,V18:V25) -> 0 | W17: =SUBTOTAL(9,W18:W25) -> 0
H18: Перебур | I18: м | J18: 1 | K18: 1 | N18: Пневмоударник DT-H4 DHD340 2-3/8 API Reg | O18: =VLOOKUP(N18,#REF!,2,FALSE) -> #REF! | P18: =J7/J24 -> 0.22293593 | Q18: =K7/K24 -> 0.20707823 | R18: =VLOOKUP(N18,#REF!,15,0) -> #REF! | S18: =IF(ISERR($P$18*$R$18)," ",($P$18*$R$18)) | T18: =IF(ISERR($Q$18*$R$18)," ",($Q$18*$R$18))
H19: Продолж-ть смены | I19: ч | J19: 10 | K19: 10 | N19: Ремкомплект DT-H4 DHD340 (внешний) | O19: =VLOOKUP(N19,#REF!,2,FALSE) -> #REF! | P19: =J7/J25 -> 0.3121103 | Q19: =K7/K25 -> 0.28990952 | R19: =VLOOKUP(N19,#REF!,15,0) -> #REF! | S19: =IF(ISERR($P$19*$R$19)," ",($P$19*$R$19)) | T19: =IF(ISERR($Q$19*$R$19)," ",($Q$19*$R$19))
H20: Скорость проходки | I20: п.м./ч | J20: 14 | K20: 14 | N20: Труба буровая ТБСУ 63,5х6,0х4700 мм | O20: =VLOOKUP(N20,#REF!,2,FALSE) -> #REF! | P20: =J7/J27 -> 0.3121103 | Q20: =K7/K27 -> 0.28990952 | R20: =VLOOKUP(N20,#REF!,15,0) -> #REF! | S20: =IF(ISERR($P$20*$R$20)," ",($P$20*$R$20)) | T20: =IF(ISERR($Q$20*$R$20)," ",($Q$20*$R$20))
B21: =C21*D34 -> 139.37961 | C21: =A10-C10-C15-C18 -> 7.225 | E21: =F21*D36 -> 190.81732 | F21: =D10-F10-F15-F18 -> 7.225 | H21: Произв-ть смены | I21: п.м./см | J21: =J19*J20 -> 140 | K21: =K19*K20 -> 140 | N21: Переводник З-50/З-66м(2паза) | O21: =VLOOKUP(N21,#REF!,2,FALSE) -> #REF! | P21: =J7/10000 -> 0.15605515 | Q21: =K7/10000 -> 0.14495476 | R21: =VLOOKUP(N21,#REF!,15,0) -> #REF! | S21: =IF(ISERR($P$21*$R$21)," ",($P$21*$R$21)) | T21: =IF(ISERR($Q$21*$R$21)," ",($Q$21*$R$21))
H22: Коэф-т исп-я обсадных | I22: % | J22: 0.1 | K22: 0.1 | N22: Труба техническая D125 SDR 26 ТУ 2248-001-49127551-2014 | O22: п.м. | P22: =J7*J22 -> 156.05515 | Q22: =K7*K22 -> 144.95476 | R22: =VLOOKUP(N22,#REF!,15,0) -> #REF! | S22: =IF(ISERR($P$22*$R$22)," ",($P$22*$R$22)) | T22: =IF(ISERR($Q$22*$R$22)," ",($Q$22*$R$22))
B23: АСП | H23: Норм. прох-ки коронки | I23: п.м. | J23: 700 | K23: 700 | N23: Коронка буровая DT-DHD340 125 мм CVD/SBL | O23: =VLOOKUP(N23,#REF!,2,FALSE) -> #REF! | P23: =J7/J23 -> 2.2293593 | Q23: =K7/K23 -> 2.0707823 | R23: =VLOOKUP(N23,#REF!,15,0) -> #REF! | S23: =IF(ISERR($P$23*$R$23)," ",($P$23*$R$23)) | T23: =IF(ISERR($Q$23*$R$23)," ",($Q$23*$R$23))
E24: ЭВВ | H24: Норм. прох-ки ППУ | I24: п.м. | J24: 7000 | K24: 7000
H25: Норм. проходки РК | I25: п.м. | J25: 5000 | K25: 5000 | N25: Доставка инструмента | O25: шт | P25: 0.5 | Q25: 0.5 | R25: 2200 | S25: =IF(ISERR($P$25*$R$25)," ",($P$25*$R$25)) -> 1100 | T25: =IF(ISERR($Q$25*$R$25)," ",($Q$25*$R$25)) -> 1100 | W25: 0
M26: 2 | N26: Постоянные расходы | S26: =SUBTOTAL(9,S28:S68) -> #REF! | T26: =SUBTOTAL(9,T28:T68) -> #REF! | U26: =SUBTOTAL(9,U28:U68) -> #REF! | V26: =SUBTOTAL(9,V28:V68) -> #REF! | W26: =SUBTOTAL(9,W28:W62) -> 0
H27: Норм. проходки штанга | I27: п.м. | J27: 5000 | K27: 5000 | M27: 2.1. | N27: Хранение, производство и доставка ВМ и СИ | S27: =SUBTOTAL(9,S28:S32) -> 48239.682 | T27: =SUBTOTAL(9,T28:T32) -> 95649.697 | U27: =SUBTOTAL(9,U28:U32) -> 48239.682 | V27: =SUBTOTAL(9,V28:V32) -> 95649.697 | W27: =SUBTOTAL(9,W28:W32) -> 0
H28: Непроизв. работа экипажа БУ | I28: см | J28: 1 | K28: 1 | N28: Стоимость хранения | S28: =S5*1.5 -> 30000 | T28: =T5*1.5 -> 30000 | U28: =U5*1.5 -> 30000 | V28: =V5*1.5 -> 30000
H29: Стоимость проживания | I29: руб | J29: 500 | K29: 500 | N29: Доставка , разгрузка ВМ | S29: 5000 | T29: 5000 | U29: 5000 | V29: 5000
H30: Выход ВГМ с 1 п.м. скважины | I30: м3 | J30: =B7/B5 -> 13.513043 | K30: =E7/E5 -> 14.608696 | N30: Энергозатраты на производство ЭВВ Березит | Q30: =Q10 -> 1.2026034 | R30: =$K$40 -> 1821.6 | T30: =K8/1000*R30 -> 43813.249 | V30: =K8/1000*R30 -> 43813.249
H31: Выход ВГМ с 1 п.м. с учетом доп. скв | I31: м3 | J31: =J4/J7 -> 12.815982 | K31: =K4/K7 -> 13.797408 | N31: Разгрузка, перевалка компонентов | P31: =P9 -> 0.94569154 | Q31: =Q10 -> 1.2026034 | R31: 700 | S31: =J8/1000*R31 -> 13239.682 | T31: =K8/1000*R31 -> 16836.448 | U31: =J8/1000*R31 -> 13239.682 | V31: =K8/1000*R31 -> 16836.448
A32: Диаметр заряда, м | D32: Вместимость, кг | H32: Удельный расход с учетом парносближенных | J32: =J8/J4 -> 0.94569154 | K32: =K8/K4 -> 1.2026034 | N32: Роялти
D33: ANFO | H33: Количество смен бурения | I33: см | J33: =J7/J21+J28 -> 12.146796 | K33: =K7/K21+K28 -> 11.353912 | M33: 2.2. | N33: Суточные, вахтовые, проживание | O33: чел | P33: кол-во см.бур. | S33: =SUBTOTAL(9,S34:S36) -> 32322.952 | T33: =SUBTOTAL(9,T34:T36) -> 36178.605 | U33: =SUBTOTAL(9,U34:U36) -> 5600 | V33: =SUBTOTAL(9,V34:V36) -> 11200 | W33: =SUBTOTAL(9,W34:W36) -> 0
A34: 0.171 | D34: =PI()*POWER(A34,2)/4*840 -> 19.291295 | H34: Количество смен заряжания | I34: см | J34: 1 | K34: 2 | N34: Суточные (хчел.*700 руб*х дней) | O34: 4 | R34: 700 | S34: =O34*J34*R34 -> 2800 | T34: =O34*K34*R34 -> 5600 | U34: =S34 -> 2800 | V34: =T34 -> 5600
D35: EMULS | N35: Вахтовые (хчел.*1500 руб*х дней) | O35: 4 | R35: 1500 | S35: =J33*$R$35 -> 18220.194 | T35: =K33*$R$35 -> 17030.867
D36: =PI()*POWER(A34,2)/4*1150 -> 26.410702 | N36: Проживание (хчел.*1000 руб*х дней) | O36: 4 | R36: 700 | S36: =$R$36*(J33+O36) -> 11302.757 | T36: =$R$36*(K33+(K34*O36)) -> 13547.738 | U36: =O36*R36*J34 -> 2800 | V36: =O36*R36*K34 -> 5600
H37: Энергозатраты на тонну ЭМ | M37: 2.3. | N37: Фонд оплаты труда | P37: кол-во чел. | S37: =SUBTOTAL(9,S38:S46) -> 165974.97 | T37: =SUBTOTAL(9,T38:T46) -> 172301.58 | U37: =SUBTOTAL(9,U38:U46) -> 53722.658 | V37: =SUBTOTAL(9,V38:V46) -> 65681.776 | W37: =SUBTOTAL(9,W38:W46) -> 0
H38: Электроэнергия, кВА | I38: 40 | J38: 7.14 | K38: =I38*J38 -> 285.6 | N38: Взрывники | P38: 3 | S38: =(S5*0.25+4500)/0.87*P38 -> 32758.621 | T38: =(T5*0.25+4500)/0.87*P38 -> 32758.621 | U38: =(U5*0.25+4500)/0.87*P38 -> 32758.621 | V38: =(V5*0.25+4500)/0.87*P38 -> 32758.621
H39: Дизельное топливо, л | I39: 32 | J39: 48 | K39: =I39*J39 -> 1536 | N39: Водитель СЗМ | P39: 1 | S39: =(P9*10*300+1500)/0.87 -> 4985.1432 | T39: =(Q10*10*300+3000)/0.87 -> 7595.1843 | U39: =(P9*10*300+2500)/0.87 -> 6134.5685 | V39: =(Q10*10*300+3000)/0.87 -> 7595.1843
K40: =K38+K39 -> 1821.6 | N40: Зав. складом ВМ | P40: 1 | S40: =30000/0.87/15 -> 2298.8506 | T40: =30000/0.87/10 -> 3448.2759 | U40: =30000/0.87/15 -> 2298.8506 | V40: =30000/0.87/10 -> 3448.2759
...

Sheet Расчет стоимости БВР
A1: Исходные данные, технические параметры для расчета | Q1: Смета затрат | Y1: =(SUM(S9:S16)+SUM(S18:S18)+SUM(S21:S22)+SUM(S24:S26)+SUM(S28:S37)+SUM(S39:S41)+SUM(S44:S47)+SUM(S49:S52)+SUM(S54:S59))*(100%+$P$61)-S62 -> 0 | Z1: =(SUM(T9:T16)+SUM(T18:T18)+SUM(T21:T22)+SUM(T24:T26)+SUM(T28:T37)+SUM(T39:T41)+SUM(T44:T47)+SUM(T49:T52)+SUM(T54:T59))*(100%+$P$61)-T62 -> 0 | AA1: =(SUM(U9:U16)+SUM(U18:U18)+SUM(U21:U22)+SUM(U24:U26)+SUM(U28:U37)+SUM(U39:U41)+SUM(U44:U47)+SUM(U49:U52)+SUM(U54:U59))*(100%+$P$61)-U62 -> 0 | AB1: =(SUM(V9:V16)+SUM(V18:V18)+SUM(V21:V22)+SUM(V24:V26)+SUM(V28:V37)+SUM(V39:V41)+SUM(V44:V47)+SUM(V49:V52)+SUM(V54:V59))*(100%+$P$61)-V62 -> 0 | AC1: =(SUM(#REF!)+SUM(#REF!)+SUM(#REF!)+SUM(#REF!)+SUM(#REF!)+SUM(#REF!)+SUM(#REF!)+SUM(#REF!)+SUM(#REF!))*(100%+$P$61)-#REF! -> #REF!
Q2: на производство взрывных работ на объекте | Y2: =S62*(100%+$P$63)-S64 -> 0 | Z2: =T62*(100%+$P$63)-T64 -> 0 | AA2: =U62*(100%+$P$63)-U64 -> 0 | AB2: =V62*(100%+$P$63)-V64 -> 0 | AC2: =(#REF!*($P$63))*1.5+#REF!-#REF! -> #REF!
Q3: "карьер Ломовского месторождения" АО "Теплогорский карьер" | Y3: проверка: если не 0 - ошибка в формулах в смете
A4: Сетка | B4: 4 | C4: 4 | D4: Сетка | E4: 3.8 | F4: 3.8
A5: Глубина | B5: 11.5 | D5: Глубина | E5: 11.5 | N5: К потерь | O5: 1
A6: Перебур | B6: 1 | D6: Перебур | E6: 1 | H6: Показатель | I6: Ед.изм | J6: ANFO | K6: EMULS | M6: № п/п | N6: Наименование | O6: Ед. изм. | P6: Норма | Q6: Норма | R6: Цена | S6: БВР сухие | T6: БВР обв | U6: ВР сухие | V6: ВР обв
A7: Удельный | B7: =B9/B8 -> 0.88088363 | D7: Удельный | E7: =E9/E8 -> 1.3362567 | H7: Объем блока | I7: м3 | J7: 30000 | K7: 30000 | M7: 1 | N7: Переменные расходы
A8: Выход | B8: =B4*C4*(B5-$B$6) -> 168 | D8: Выход | E8: =E4*F4*(E5-$E$6) -> 151.62 | H8: Кол-во скважин | I8: шт. | J8: =J7/$B$8 -> 178.57143 | K8: =K7/$E$8 -> 197.86308 | M8: 1.1. | N8: Расходы на ВМ
A9: Заряд | B9: =B22+B16 -> 147.98845 | D9: Заряд | E9: =E22+E16 -> 202.60324 | H9: Процент добавочных скважин | I9: % | J9: 0.03 | K9: 0.03 | N9: ГВВ Гранулит РП | O9: =LOOKUP(N9,ВВ!$A$3:$A$12,ВВ!$B$3:$B$12) -> кг | P9: =$J$35 -> 0.90731014 | Q9: X | R9: =LOOKUP(N9,ВВ!$A$3:$A$12,ВВ!$C$3:$C$12) -> 46 | S9: =P9*J7*R9 -> 1252088 | T9: Х | U9: =S9 -> 1252088 | V9: Х
H10: Добавочные скважины | I10: шт. | J10: =J8*J9 -> 5.3571429 | K10: =K8*K9 -> 5.9358924 | N10: ЭВВ Эверсин-100 | O10: =LOOKUP(N10,ВВ!$A$3:$A$12,ВВ!$B$3:$B$12) -> кг | P10: X | Q10: =K35 -> 1.3763444 | R10: =LOOKUP(N10,ВВ!$A$3:$A$12,ВВ!$C$3:$C$12) -> 48.9 | S10: Х | T10: =K7*Q10*R10 -> 2019097.2 | U10: Х | V10: =T10 -> 2019097.2
A11: =B5 -> 11.5 | C11: =A35*15 -> 2.3484 | D11: =E5 -> 11.5 | F11: =A35*15 -> 2.3484 | H11: Скважины конверта | I11: шт. | J11: 0 | K11: 0 | N11: Детонатор промежуточный "Сферит ДП" - 60 / 1,0 | O11: =LOOKUP(N11,ВВ!$A$3:$A$12,ВВ!$B$3:$B$12) -> кг | P11: =J22/J7*1000 -> 9.8095238 | Q11: Х | R11: =LOOKUP(N11,СВ!A3:A20,СВ!D3:D20) -> 0 | T11: Х | V11: Х
H12: Глубина скважин конверта | I12: м | J12: 0 | K12: 0 | N12: =H22 -> Детонатор промежуточный ДПУ-ПТ600 | O12: =LOOKUP(N12,ВВ!$A$3:$A$12,ВВ!$B$3:$B$12) -> кг | P12: Х | Q12: =K22/K7*1000 -> 10.869278 | S12: Х | U12: X
H13: Кол-во п.м. конверта | I13: п.м. | J13: =J11*J12 -> 0 | K13: =K11*K12 -> 0 | N13: =H28 -> Устройство Искра-С-*-12 | O13: =LOOKUP(N13,ВВ!$A$3:$A$12,ВВ!$B$3:$B$12) -> кг | P13: =J28/J7*1000 -> 6.1922619 | Q13: =K28/K7*1000 -> 6.793299 | R13: =LOOKUP(N13,ВВ!$A$3:$A$12,ВВ!$C$3:$C$12) -> 46 | S13: =IF(ISERR($P$13*$R$13)," ",($P$13*$R$13))/1000*$J$7 -> 8545.3214 | T13: =IF(ISERR($Q$13*$R$13)," ",($Q$13*$R$13))/1000*$K$7 -> 9374.7527 | U13: =IF(ISERR($P$13*$R$13)," ",($P$13*$R$13))/1000*$J$7 -> 8545.3214 | V13: =IF(ISERR($Q$13*$R$13)," ",($Q$13*$R$13))/1000*$K$7 -> 9374.7527
H14: Длина заряда | I14: м | J14: 0 | K14: 0 | N14: =H29 -> Устройство Искра-П-*-5 | O14: =LOOKUP(N14,ВВ!$A$3:$A$12,ВВ!$B$3:$B$12) -> кг | P14: =J29/J7*1000 -> 0.61922619 | Q14: =K29/K7*1000 -> 0.6861232 | R14: =LOOKUP(N14,ВВ!$A$3:$A$12,ВВ!$C$3:$C$12) -> 46 | S14: =IF(ISERR($P$14*$R$14)," ",($P$14*$R$14))/1000*$J$7 -> 854.53214 | T14: =IF(ISERR($Q$14*$R$14)," ",($Q$14*$R$14))/1000*$K$7 -> 946.85002 | U14: =IF(ISERR($P$14*$R$14)," ",($P$14*$R$14))/1000*$J$7 -> 854.53214 | V14: =IF(ISERR($Q$14*$R$14)," ",($Q$14*$R$14))/1000*$K$7 -> 946.85002
H15: Масса ВВ (конверт) | I15: кг. | N15: =H30 -> Устройство Искра-П-*-5 | O15: =LOOKUP(N15,ВВ!$A$3:$A$12,ВВ!$B$3:$B$12) -> кг | P15: =J30/J7*1000 -> 5.5730357 | Q15: =K30/K7*1000 -> 6.1751088 | R15: =LOOKUP(N15,ВВ!$A$3:$A$12,ВВ!$C$3:$C$12) -> 46 | S15: =IF(ISERR($P$15*$R$15)," ",($P$15*$R$15))/1000*$J$7 -> 7690.7893 | T15: =IF(ISERR($Q$15*$R$15)," ",($Q$15*$R$15))/1000*$K$7 -> 8521.6502 | U15: =IF(ISERR($P$15*$R$15)," ",($P$15*$R$15))/1000*$J$7 -> 7690.7893 | V15: =IF(ISERR($Q$15*$R$15)," ",($Q$15*$R$15))/1000*$K$7 -> 8521.6502
H16: Кол-во п.м. | I16: п.м. | J16: =(J8+J10)*B5 -> 2115.1786 | K16: =(K8+K10)*E5 -> 2343.6882 | N16: =H31 -> Устройство ИСКРА-СТАРТ-В-500 | O16: =LOOKUP(N16,ВВ!$A$3:$A$12,ВВ!$B$3:$B$12) -> кг | P16: =J31/J7*1000 -> 0.033333333 | Q16: =K31/K7*1000 -> 0.033333333 | R16: =LOOKUP(N16,ВВ!$A$3:$A$12,ВВ!$C$3:$C$12) -> 46 | S16: =IF(ISERR($P$16*$R$16)," ",($P$16*$R$16))/1000*$J$7 -> 46 | T16: =IF(ISERR($Q$16*$R$16)," ",($Q$16*$R$16))/1000*$K$7 -> 46 | U16: =IF(ISERR($P$16*$R$16)," ",($P$16*$R$16))/1000*$J$7 -> 46 | V16: =IF(ISERR($Q$16*$R$16)," ",($Q$16*$R$16))/1000*$K$7 -> 46
H17: Масса ВВ | I17: кг. | J17: =(J8+J10)*$B$9 -> 27219.304 | K17: =(K8+K10)*$E$9+(K11*K14*K15) -> 41290.331 | M17: 1.2. | N17: Расходы на бурение скважин | S17: =SUBTOTAL(9,S18:S18) -> 2133523.8 | T17: =SUBTOTAL(9,T18:T18) -> 2364015.3 | U17: =SUBTOTAL(9,U18:U18) -> 0 | V17: =SUBTOTAL(9,V18:V18) -> 0 | W17: =#REF! -> #REF! | X17: =W17 -> #REF!
H18: Общее количество скважин | I18: шт. | J18: =J8+J10 -> 183.92857 | K18: =K8+K10 -> 203.79897 | N18: Потребность в бурении | O18: п.м. | P18: =J34 -> 14.1832 | Q18: =K34 -> 12.800338 | R18: ='Расчет стоимости бурения'!D41 -> 1008.6731 | S18: =J7/P18*R18 -> 2133523.8 | T18: =K7/Q18*R18 -> 2364015.3 | U18: Х | V18: Х | W18: =S18/J7 -> 71.117461 | X18: =T18/K7 -> 78.800511
H19: Промежуточные детонаторы основных зарядов | M19: 2 | N19: Постоянные расходы | S19: =SUBTOTAL(9,S21:S59) -> 410987.33 | T19: =SUBTOTAL(9,T21:T59) -> 454706.14 | U19: =SUBTOTAL(9,U21:U59) -> 353165.33 | V19: =SUBTOTAL(9,V21:V59) -> 396884.14
H20: Резервирование | M20: 2.1. | N20: Хранение, производство и доставка ВМ и СИ | S20: =SUBTOTAL(9,S21:S22) -> 51000 | T20: =SUBTOTAL(9,T21:T22) -> 51000 | U20: =SUBTOTAL(9,U21:U22) -> 51000 | V20: =SUBTOTAL(9,V21:V22) -> 51000
H21: Дублирование | I21: X | J21: 2 | K21: 2 | N21: Стоимость хранения | S21: =J7*1.5 -> 45000 | T21: =K7*1.5 -> 45000 | U21: =J7*1.5 -> 45000 | V21: =K7*1.5 -> 45000
B22: =C22*D35 -> 147.98845 | C22: =A11-C11-C16-C19 -> 9.1516 | E22: =F22*D37 -> 202.60324 | F22: =D11-F11-F16-F19 -> 9.1516 | H22: Детонатор промежуточный ДПУ-ПТ600 | I22: кг. | J22: =LOOKUP($H$22,СВ!$A$3:$A$20,СВ!$C$3:$C$20)*$J$18*$J$21 -> 294.28571 | K22: =LOOKUP($H$22,СВ!$A$3:$A$18,СВ!$C$3:$C$18)*$K$18*$K$21 -> 326.07835 | N22: Доставка , разгрузка ВМ | S22: =J7*0.2 -> 6000 | T22: =K7*0.2 -> 6000 | U22: =J7*0.2 -> 6000 | V22: =K7*0.2 -> 6000
H23: Промежуточные детонаторы для зарядов конверта | M23: 2.2. | N23: Суточные, вахтовые, проживание | P23: чел | Q23: чел | S23: =SUBTOTAL(9,S24:S26) -> 5000 | T23: =SUBTOTAL(9,T24:T26) -> 12000 | U23: =SUBTOTAL(9,U24:U26) -> 5000 | V23: =SUBTOTAL(9,V24:V26) -> 12000
B24: АСП | H24: Детонатор промежуточный "Сферит ДП" - 60 / 0,8 | I24: кг. | J24: =LOOKUP(H24,СВ!A3:A20,СВ!C3:C20)*$J$11 -> 0 | K24: =LOOKUP(H24,СВ!A3:A20,СВ!C3:C20)*$K$11 -> 0 | N24: Суточные (хчел.*1000 руб*х дней) | P24: =P28+P29+P31+P32 -> 5 | Q24: =P28+P29+P30+P31+P32 -> 6 | R24: 1000 | S24: =P24*(J36/2)*R24 -> 5000 | T24: =Q24*(K36/2)*R24 -> 6000 | U24: =P24*(J36/2)*R24 -> 5000 | V24: =Q24*(K36/2)*R24 -> 6000
E25: ЭВВ | H25: Средства инициирования | N25: Вахтовые (хчел.*1500 руб*х дней) | S25: Х | T25: Х | U25: Х | V25: Х
H26: Резервирование | I26: % | J26: 1.01 | K26: 1.01 | N26: Проживание (хчел.*1000 руб*х дней) | Q26: =Q24 -> 6 | R26: 1000 | S26: Х | T26: =$R$26*(K36/2)*Q26 -> 6000 | U26: =O26*R26*J33 -> 0 | V26: =$Q$26*(K36/2)*R26 -> 6000
H27: Дублирование | I27: X | J27: 1 | K27: 1 | M27: 2.3. | N27: Фонд оплаты труда | P27: кол-во чел. | Q27: Оклад | R27: Сдельная расценка | S27: =SUBTOTAL(9,S28:S41) -> 193018.38 | T27: =SUBTOTAL(9,T28:T41) -> 229737.19 | U27: =SUBTOTAL(9,U28:U41) -> 193018.38 | V27: =SUBTOTAL(9,V28:V41) -> 229737.19
H28: Устройство Искра-С-*-12 | I28: шт. | J28: =J$18*J27*(J26) -> 185.76786 | K28: =K$18 -> 203.79897 | M28: 1 | N28: Руководитель взрывных работ (мастер БВР) | P28: 1 | Q28: 80000 | R28: 0.25 | S28: =(($J$7*$R$28+$Q$28/5)*$P$28)/0.85 -> 27647.059 | T28: =(($K$7*$R$28+$Q$28/5)*$P$28)/0.85 -> 27647.059 | U28: =(($J$7*$R$28+$Q$28/5)*$P$28)/0.85 -> 27647.059 | V28: =(($K$7*$R$28+$Q$28/5)*$P$28)/0.85 -> 27647.059
H29: Устройство Искра-П-*-5 | I29: шт. | J29: =J$18*0.1*J26 -> 18.576786 | K29: =K$18*0.1*K26 -> 20.583696 | M29: =M28+1 -> 2 | N29: Взрывники | P29: 2 | Q29: 55000 | R29: 0.25 | S29: =(($J$7*$R$29+$Q$29/5)*$P$29)/0.85 -> 43529.412 | T29: =(($K$7*$R$29+$Q$29/5)*$P$29)/0.85 -> 43529.412 | U29: =(($J$7*$R$29+$Q$29/5)*$P$29)/0.85 -> 43529.412 | V29: =(($K$7*$R$29+$Q$29/5)*$P$29)/0.85 -> 43529.412
H30: Устройство Искра-П-*-5 | I30: шт. | J30: =J$18*0.9*J26 -> 167.19107 | K30: =K$18*0.9*K26 -> 185.25326 | M30: =M29+1 -> 3 | N30: Горнорабочий | P30: 1 | Q30: 35000 | R30: 0.15 | S30: Х | T30: =(($K$7*$R$30+$Q$30/5)*$P$30)/0.85 -> 13529.412 | U30: Х | V30: =(($K$7*$R$30+$Q$30/5)*$P$30)/0.85 -> 13529.412
H31: Устройство ИСКРА-СТАРТ-В-500 | I31: шт. | J31: 1 | K31: 1 | M31: =M30+1 -> 4 | N31: Водитель СЗМ | P31: 1 | Q31: 60000 | R31: 0.3 | S31: =(($J$17*$R$31+$Q$31/5)*$P$31)/0.85 -> 23724.46 | T31: =(($K$17*$R$31+$Q$31/5)*$P$31)/0.85 -> 28690.705 | U31: =(($J$17*$R$31+$Q$31/5)*$P$31)/0.85 -> 23724.46 | V31: =(($K$17*$R$31+$Q$31/5)*$P$31)/0.85 -> 28690.705
M32: =M31+1 -> 5 | N32: Водитель доставщика | P32: 1 | Q32: 80000 | R32: 0.3 | S32: =(($J$17*$R$32+$Q$32/5)*$P$32)/0.85 -> 28430.343 | T32: =(($K$17*$R$32+$Q$32/5)*$P$32)/0.85 -> 33396.587 | U32: =(($J$17*$R$32+$Q$32/5)*$P$32)/0.85 -> 28430.343 | V32: =(($K$17*$R$32+$Q$32/5)*$P$32)/0.85 -> 33396.587
A33: Диаметр заряда, м | D33: Вместимость, кг | H33: Выход ВГМ с 1 п.м. скважины | I33: м3 | J33: =$B$8/$B$5 -> 14.608696 | K33: =$B$8/$B$5 -> 14.608696 | M33: =M32+1 -> 6
D34: ANFO | H34: Выход ВГМ с 1 п.м. с учетом доп. скв | I34: м3 | J34: =$J$7/$J$16 -> 14.1832 | K34: =$K$7/$K$16 -> 12.800338 | M34: =M33+1 -> 7
A35: =0.152*1.03 -> 0.15656 | D35: =PI()*POWER(A35,2)/4*840 -> 16.170773 | H35: Удельный расход с учетом парносближенных | J35: =$J$17/$J$7 -> 0.90731014 | K35: =$K$17/$K$7 -> 1.3763444 | M35: =M34+1 -> 8 | W35: =#REF! -> #REF! | X35: =W35 -> #REF!
D36: EMULS | H36: Количество смен заряжания | I36: см | J36: 2 | K36: 2 | M36: =M35+1 -> 9
D37: =PI()*POWER(A35,2)/4*1150 -> 22.138559 | M37: =M36+1 -> 10 | W37: =#REF! -> #REF! | X37: =W37 -> #REF!
N38: Итого заработная плата | P38: =SUM(P28:P37) -> 6 | S38: =SUBTOTAL(9,S28:S37) -> 123331.27 | T38: =SUBTOTAL(9,T28:T37) -> 146793.17 | U38: =SUBTOTAL(9,U28:U37) -> 123331.27 | V38: =SUBTOTAL(9,V28:V37) -> 146793.17
N39: Отчисления от несчастного случая | P39: 0.0042 | S39: =S38*$P$39 -> 517.99135 | T39: =T38*$P$39 -> 616.53133 | U39: =U38*$P$39 -> 517.99135 | V39: =V38*$P$39 -> 616.53133
D40: S | E40: a | F40: b | G40: V | H40: q | I40: ВР | J40: БВР | K40: Цена за метр | N40: Отчисления в фонды социального страхования | P40: 0.3 | S40: =S38*$P$40 -> 36999.382 | T40: =T38*$P$40 -> 44037.952 | U40: =U38*$P$40 -> 36999.382 | V40: =V38*$P$40 -> 44037.952
...

Sheet Тарифная сетка
C1: Сетка | F1: Стоимость единицы продукции без учета НДС, руб.
A2: Площадь, м2 | B2: Диаметр, м | C2: А, м | D2: B, м | E2: Погонаж, м | F2: ВР на м3 | G2: БВР | H2: БР на п.м. | I2: БР на м3 | J2: Комплекс | K2: Удельный
A3: 12.25 | B3: 0.16 | C3: =SQRT(A3) -> 3.5 | D3: =C3 -> 3.5 | E3: =70027*A3^(-1.006) -> 5631.1956 | F3: =-3.4054*A3+118.76 -> 77.04385 | G3: =1913.2*A3^(-0.927) -> 187.52459 | H3: =(4.0554*A3 + 800)*1.2 -> 1019.6144 | I3: =E3*H3/'Расчет стоимости БВР'!$K$7 -> 191.38827 | J3: =F3+I3 -> 268.43212 | K3: 1.653904
A4: 12.96 | B4: 0.16 | C4: =SQRT(A4) -> 3.6 | D4: =C4 -> 3.6 | E4: =70027*A4^(-1.006) -> 5320.8975 | F4: =-3.4054*A4+118.76 -> 74.626016 | G4: =1913.2*A4^(-0.927) -> 177.98178 | H4: =(4.0554*A4 + 800)*1.2 -> 1023.0696 | I4: =E4*H4/'Расчет стоимости БВР'!$K$7 -> 181.45494 | J4: =F4+I4 -> 256.08096 | K4: 1.5632966
A5: 13.69 | B5: 0.16 | C5: =SQRT(A5) -> 3.7 | D5: =C5 -> 3.7 | E5: =70027*A5^(-1.006) -> 5035.5122 | F5: =-3.4054*A5+118.76 -> 72.140074 | G5: =1913.2*A5^(-0.927) -> 169.1665 | H5: =(4.0554*A5 + 800)*1.2 -> 1026.6221 | I5: =E5*H5/'Расчет стоимости БВР'!$K$7 -> 172.31894 | J5: =F5+I5 -> 244.45901 | K5: 1.479936
A6: 14.44 | B6: 0.16 | C6: =SQRT(A6) -> 3.8 | D6: =C6 -> 3.8 | E6: =70027*A6^(-1.006) -> 4772.4449 | F6: =-3.4054*A6+118.76 -> 69.586024 | G6: =1913.2*A6^(-0.927) -> 161.00582 | H6: =(4.0554*A6 + 800)*1.2 -> 1030.272 | I6: =E6*H6/'Расчет стоимости БВР'!$K$7 -> 163.89721 | J6: =F6+I6 -> 233.48323 | K6: 1.4030695
A7: 15.21 | B7: 0.16 | C7: =SQRT(A7) -> 3.9 | D7: =C7 -> 3.9 | E7: =70027*A7^(-1.006) -> 4529.4298 | F7: =-3.4054*A7+118.76 -> 66.963866 | G7: =1913.2*A7^(-0.927) -> 153.43576 | H7: =(4.0554*A7 + 800)*1.2 -> 1034.0192 | I7: =E7*H7/'Расчет стоимости БВР'!$K$7 -> 156.11724 | J7: =F7+I7 -> 223.08111 | K7: 1.3320397
A8: 16 | B8: 0.16 | C8: =SQRT(A8) -> 4 | D8: =C8 -> 4 | E8: =70027*A8^(-1.006) -> 4304.4812 | F8: =-3.4054*A8+118.76 -> 64.2736 | G8: =1913.2*A8^(-0.927) -> 146.40002 | H8: =(4.0554*A8 + 800)*1.2 -> 1037.8637 | I8: =E8*H8/'Расчет стоимости БВР'!$K$7 -> 148.91549 | J8: =F8+I8 -> 213.18909 | K8: 1.2662702
A9: 16.81 | B9: 0.16 | C9: =SQRT(A9) -> 4.1 | D9: =C9 -> 4.1 | E9: =70027*A9^(-1.006) -> 4095.8534 | F9: =-3.4054*A9+118.76 -> 61.515226 | G9: =1913.2*A9^(-0.927) -> 139.84892 | H9: =(4.0554*A9 + 800)*1.2 -> 1041.8055 | I9: =E9*H9/'Расчет стоимости БВР'!$K$7 -> 142.23609 | J9: =F9+I9 -> 203.75132 | K9: 1.2052542
A10: 17.64 | B10: 0.16 | C10: =SQRT(A10) -> 4.2 | D10: =C10 -> 4.2 | E10: =70027*A10^(-1.006) -> 3902.0061 | F10: =-3.4054*A10+118.76 -> 58.688744 | G10: =1913.2*A10^(-0.927) -> 133.73842 | H10: =(4.0554*A10 + 800)*1.2 -> 1045.8447 | I10: =E10*H10/'Расчет стоимости БВР'!$K$7 -> 136.02975 | J10: =F10+I10 -> 194.71849 | K10: 1.1485444
A11: 18.49 | B11: 0.16 | C11: =SQRT(A11) -> 4.3 | D11: =C11 -> 4.3 | E11: =70027*A11^(-1.006) -> 3721.5768 | F11: =-3.4054*A11+118.76 -> 55.794154 | G11: =1913.2*A11^(-0.927) -> 128.02944 | H11: =(4.0554*A11 + 800)*1.2 -> 1049.9812 | I11: =E11*H11/'Расчет стоимости БВР'!$K$7 -> 130.25286 | J11: =F11+I11 -> 186.04701 | K11: 1.0957449
A12: 19.36 | B12: 0.16 | C12: =SQRT(A12) -> 4.4 | D12: =C12 -> 4.4 | E12: =70027*A12^(-1.006) -> 3553.3561 | F12: =-3.4054*A12+118.76 -> 52.831456 | G12: =1913.2*A12^(-0.927) -> 122.68716 | H12: =(4.0554*A12 + 800)*1.2 -> 1054.2151 | I12: =E12*H12/'Расчет стоимости БВР'!$K$7 -> 124.86672 | J12: =F12+I12 -> 177.69817 | K12: 1.0465043
A13: 20.25 | B13: 0.16 | C13: =SQRT(A13) -> 4.5 | D13: =C13 -> 4.5 | E13: =70027*A13^(-1.006) -> 3396.2679 | F13: =-3.4054*A13+118.76 -> 49.80065 | G13: =1913.2*A13^(-0.927) -> 117.68046 | H13: =(4.0554*A13 + 800)*1.2 -> 1058.5462 | I13: =E13*H13/'Расчет стоимости БВР'!$K$7 -> 119.83689 | J13: =F13+I13 -> 169.63754 | K13: 1.0005098
B16: Примечание | C16: Фактический толеранс по удельному расходу +-0,1 кг/м3

Sheet Расчет стоимости бурения
B1: Объект | C1: "карьер Ломовского месторождения" АО "Теплогорский карьер" | D1: Цена за ед, руб.
B3: Объем буровых работ, м | C3: ='Расчет стоимости БВР'!K16 -> 2343.6882
B5: Диаметр коронки, мм | C5: 152
B6: Тип буровой установки | C6: JK 830-3
B7: Технологическая скорость бурения, м/час | C7: 12
B8: Непроизводительное время в смену, час | C8: 1
B9: Коммерческая скорость бурения, м/смену | C9: =C7*(11-C8) -> 120
B10: Расход дизельного топлива, л/час | C10: =_xlfn.XLOOKUP(C6,Таблица1[Нименование],Таблица1[Норма расхода ДТ, л.]) -> 50
B11: Расход дизельного топлива, л/метр | C11: =C10/C7 -> 4.1666667
B12: Аммортизация, руб./смену | C12: =_xlfn.XLOOKUP('Расчет стоимости бурения'!C6, 'ОС Буровые'!B2:B7, 'ОС Буровые'!G2:G7) -> 11854.167 | D12: =C12*(C20+C21+C22)/C3 -> 113.95846
B13: Расход буровой коронки, метров/шт | C13: 700 | D13: 25000
B14: Расход буровой коронки, шт/метр | C14: =1/C13 -> 0.0014285714 | D14: =C14*D13 -> 35.714286
B15: Расход ППУ, метров/шт | C15: 7000 | D15: 100000
B16: Расход ППУ, шт/метр | C16: =1/C15 -> 0.00014285714 | D16: =C16*D15 -> 14.285714
B17: Расход буровой оснастки, метров/компл. | C17: 15000 | D17: =60000+70000+25000 -> 155000
B18: Расход буровой оснастки (штанги, переводники, ремкомплекты), компл./метр | C18: =1/15000 -> 6.6666667e-05 | D18: =C18*D17 -> 10.333333
B19: Расход обсадной трубы, метр/метр | C19: 0.03 | D19: =C19*450 -> 13.5
B20: Количество смен бурения, смены | C20: =C3/C9 -> 19.530735
B21: Количество смен на ТОиР, смены | C21: 2
B22: Количество смен на прочистку скв., смены | C22: 1
B23: Запасные части, руб. | C23: =C3*30 -> 70310.645 | D23: =C23/C3 -> 30
B24: Расходные материалы (ГСМ, фильтры), руб. | C24: =C3*10 -> 23436.882 | D24: =C24/C3 -> 10
B25: ФОТ основного персонала с НДФЛ, руб | C25: =(C3*150)/0.85 -> 413592.03
B26: Отчисления ФОТ, руб. | C26: =C25*1.42 -> 587300.68 | D26: =C26/C3 -> 250.58824
B27: Цена ДТ, руб./тн | C27: =_xlfn.XLOOKUP(C1, 'Объекты работ'!A2:A29, 'Объекты работ'!E2:E29) -> 80000
B28: Расход ДТ общий, л | C28: =C3*C11 -> 9765.3674
B29: Стоимость ДТ, руб. | C29: =C28*0.85*C27/1000 -> 664044.98 | D29: =C29/C3 -> 283.33333
B30: Расстояние мобилизации, км | C30: =_xlfn.XLOOKUP(C1, 'Объекты работ'!A2:A29, 'Объекты работ'!B2:B29) -> 300
B31: Стоиомсть мобилизации буровой установки, руб. | C31: =C30*450 -> 135000 | D31: =C31/(C3 * 6) -> 9.6002533
B32: Выпуск на линию (тех. осмотр), руб. | C32: =(C20+C21+C22)*2*100 -> 4506.1469 | D32: =C32/C3 -> 1.9226734
B33: Медосмотры, руб. | C33: =C32 -> 4506.1469 | D33: =C33/C3 -> 1.9226734
B34: Суточные/вахтовые, руб.
B35: Питание, руб.
B36: Проживание, руб.
B37: Итого прямые расходы | D37: =D14+D16+D19+D12+D23+D24+D26+D29+D32+D33 -> 755.22537
B38: Общепроизводственные расходы, руб. | C38: 100000 | D38: =C38/C3 -> 42.667792
B39: Накладные расходы, руб. | C39: 100000 | D39: =C39/C3 -> 42.667792
B40: Итого себестоимость | D40: =D37+D38+D39 -> 840.56096
B41: Прибыль, руб. | D41: =D40*1.2 -> 1008.6731
B42: Доля дизельного топлива, % | D42: =C29/C3/D41 -> 0.28089707

Sheet ОС Буровые
A1: № п/п | B1: Нименование | C1: Дата ввода | D1: Первоначальная стоимость, руб. | E1: СПИ | F1: Ам норма/мес, руб. | G1: Ам норма/смену, руб. | H1: Норма расхода ДТ, л.
A2: 1 | B2: Soosan JD-2000 | D2: 34200000 | E2: 60 | F2: =D2/E2 -> 570000 | G2: =F2/40 -> 14250 | H2: 55
A3: 2 | B3: ZEGA D480A | D3: 30000000 | E3: 60 | F3: =D3/E3 -> 500000 | G3: =F3/40 -> 12500 | H3: 55
A4: 3 | B4: JK 830-3 | D4: 28450000 | E4: 60 | F4: =D4/E4 -> 474166.67 | G4: =F4/40 -> 11854.167 | H4: 50
A5: 4 | B5: TM255-T | D5: 18000000 | E5: 60 | F5: =D5/E5 -> 300000 | G5: =F5/40 -> 7500 | H5: 26
A6: 5 | B6: УРБ-2А2 + компрессор | D6: 8500000 | E6: 60 | F6: =D6/E6 -> 141666.67 | G6: =F6/40 -> 3541.6667 | H6: 45
A7: 6 | B7: УРБ-2А2 + компрессор | D7: 5500000 | E7: 60 | F7: =D7/E7 -> 91666.667 | G7: =F7/40 -> 2291.6667 | H7: 30

Sheet Объекты работ
A1: Наименование объекта | B1: Расстояние от базы | C1: Расстояние от склада | E1: цена ДТ за тн без учета НДС
A2: "карьер м-ия Анна" ООО "СУПБ" | B2: 650 | C2: 600
A3: "карьер м-ия С-Саркаевское" ООО "Ергач" | B3: 350 | C3: 410
A4: "карьер м-ия В-Вильвенское" ООО "ГХК" | B4: 270 | C4: 350
A5: "карьер м-ия Заготовкинское" ООО "ГДК" | B5: 100 | C5: 170
A6: "карьер м-ия Ломовское" АО "ТК" | B6: 220 | C6: 270 | E6: 52200
A7: "карьер м-ия гора Матюковая" ПАО "АВИСМА" | B7: 290 | C7: 320
A8: "карьер Чаньвинский" АО "БСЗ" | B8: 320 | C8: 350
A9: "карьер Разепинский" ООО "ПГК" | B9: 300 | C9: 400
A10: "карьер м-ия Дружининское" ООО "АПИ Транзит" | B10: 700 | C10: 800
A11: "карьер м-ия Пудлинговое" ООО "ПуЩЗ" | B11: 570 | C11: 650
A12: "карьер месторождения Чинья-Ворыкское" ООО "Автодор" | B12: 2600 | C12: 2800
A13: "карьер месторождения Бельгопское" ООО "УЗСМ" | B13: 2800 | C13: 3000
A14: "вертолетная площадка Усть-Лыжа" | B14: 3500 | C14: 3700
A15: "карьер месторождения Пикинское" АО "ЧК" | B15: 1600 | C15: 1800
A16: "карьер месторождения Шипичатское" ООО "ВК-Трейд" | B16: 1500 | C16: 1700
A17: "карьер месторождения Пещерное" ООО "СГТ" | B17: 700 | C17: 620
A18: "карьер месторождения Заплотный камень ООО "ЗК" | B18: 620 | C18: 570
... A27: "карьер Малодегтярского месторождения" ООО "МК" | B27: 600 | C27: 700
A28: "карьер Чаньвинского месторождения известняков" АО "БСЗ" | B28: 320 | C28: 360 | E28: 68000
A29: "карьер Ломовского месторождения" АО "Теплогорский карьер" | B29: 300 | C29: 300 | E29: 80000

Sheet Лист5

Sheet расчет 165 4,0х4,5
A1: Исходные данные, технические параметры для расчета | Q1: Смета затрат | Z1: =(SUM(S9:S16)+SUM(S18:S25)+SUM(S28:S32)+SUM(S34:S36)+SUM(S38:S47)+SUM(S49:S50)+SUM(S53:S58)+SUM(S60:S65)+SUM(S67:S72))*(100%+$P$78)-S79 -> 0 | AA1: =(SUM(T9:T16)+SUM(T18:T25)+SUM(T28:T32)+SUM(T34:T36)+SUM(T38:T47)+SUM(T49:T50)+SUM(T53:T58)+SUM(T60:T65)+SUM(T67:T72))*(100%+$P$78)-T79 -> 0 | AB1: =(SUM(U9:U16)+SUM(U18:U25)+SUM(U28:U32)+SUM(U34:U36)+SUM(U38:U47)+SUM(U49:U50)+SUM(U53:U58)+SUM(U60:U65)+SUM(U67:U72))*(100%+$P$78)-U79 -> 0 | AC1: =(SUM(V9:V16)+SUM(V18:V25)+SUM(V28:V32)+SUM(V34:V36)+SUM(V38:V47)+SUM(V49:V50)+SUM(V53:V58)+SUM(V60:V65)+SUM(V67:V72))*(100%+$P$78)-V79 -> 0 | AD1: =(SUM(W9:W16)+SUM(W18:W25)+SUM(W28:W32)+SUM(W34:W36)+SUM(W38:W47)+SUM(W49:W50)+SUM(W53:W58)+SUM(W60:W65)+SUM(W67:W72))*(100%+$P$78)-W79 -> 0
Q2: на производство взрывных работ на объекте | Z2: =S79*(100%+$P$80)-S81 -> 0 | AA2: =T79*(100%+$P$80)-T81 -> 0 | AB2: =U79*(100%+$P$80)-U81 -> 0 | AC2: =V79*(100%+$P$80)-V81 -> 0 | AD2: =(W79*($P$80))*1.5+W79-W81 -> 0
H3: Показатель | I3: Ед.изм | J3: ANFO | K3: EMULS | Q3: ='Объекты работ'!A6 -> "карьер м-ия Ломовское" АО "ТК" | W3: пм | Z3: проверка: если не 0 - ошибка в формулах в смете
A4: Сетка | B4: 3.7 | C4: 4.2 | D4: Сетка | E4: 3.8 | F4: 3.8 | H4: Объем блока | I4: м3 | J4: =S5 -> 30000 | K4: =T5 -> 30000 | R4: базовый тариф
A5: Глубина | B5: 11 | D5: Глубина | E5: 11 | H5: Кол-во скважин | I5: шт. | J5: =J4/B7 -> 203.21073 | K5: =K4/E7 -> 218.69077 | N5: К потерь | O5: 1 | R5: Объем справочно, м3 | S5: 30000 | T5: =S5 -> 30000 | U5: =S5 -> 30000 | V5: =T5 -> 30000 | W5: =S5/((J36+K36)/2) -> 2394.4347
A6: Удельный | B6: =B8/B7 -> 0.86579764 | D6: Удельный | E6: =E8/E7 -> 1.4539711 | H6: Добавочные скважины | I6: шт. | J6: 7 | K6: 7 | M6: № п/п | N6: Наименование | O6: Ед. изм. | P6: Норма const ANFO (кг./л.//1000 м3) | Q6: Норма const EMULS (кг./л.//1000 м3) | R6: Цена (руб./шт, тн) | S6: БВР сухие | T6: БВР обв | U6: ВР сухие | V6: ВР обв | W6: Бурение
A7: Выход | B7: =B4*C4*(B5-$J$23) -> 147.63 | D7: Выход | E7: =E4*F4*(E5-$J$23) -> 137.18 | H7: Скважины конверта | I7: шт. | J7: 0 | K7: 0 | M7: 1 | N7: Переменные расходы
A8: Заряд | B8: =B21+B15 -> 127.81771 | D8: Заряд | E8: =E21+E15 -> 199.45575 | H8: Глубина | I8: м | J8: 0 | K8: 0 | M8: 1.1. | N8: Расходы на ВМ | S8: =SUBTOTAL(9,S9:S16) -> 866372.73 | T8: =SUBTOTAL(9,T9:T16) -> 140858.58 | U8: =SUBTOTAL(9,U9:U16) -> 893935.62 | V8: =SUBTOTAL(9,V9:V16) -> 2367469.5 | W8: =SUBTOTAL(9,W9:W16) -> 0
H9: Кол-во п.м. конверта | I9: п.м. | J9: =J7*J8 -> 0 | K9: =K7*K8 -> 0 | N9: Гранулит АСП-1 | O9: тн | P9: =J37 -> 0.89562177 | Q9: 0 | R9: =VLOOKUP(N9, '3.сырье'!B27:Q35,16,0) -> 22640 | S9: =IF(ISERR($P$9*$R$9)," ",($P$9*$R$9))/1000*$S$5 -> 608306.31 | T9: =IF(ISERR($Q$9*$R$9)," ",($Q$9*$R$9))/1000*$T$5 -> 0 | U9: =IF(ISERR($P$9*$R$9)," ",($P$9*$R$9))/1000*$U$5 -> 608306.31 | V9: =IF(ISERR($Q$9*$R$9)," ",($Q$9*$R$9))/1000*$V$5 -> 0
A10: =B5 -> 11 | C10: =A34*20 -> 3.14 | D10: =E5 -> 11 | F10: =A34*13 -> 2.041 | H10: Длина заряда | I10: м | J10: 0 | K10: 0 | N10: Эмульсионная матрица | O10: тн | P10: 0 | Q10: =K37 -> 1.5005107 | R10: 48.9 | S10: =IF(ISERR($P$10*$R$10)," ",($P$10*$R$10))/1000*$S$5 -> 0 | T10: =IF(ISERR($Q$10*$R$10)," ",($Q$10*$R$10))/1000*$T$5 -> 2201.2493 | U10: =IF(ISERR($P$10*$R$10)," ",($P$10*$R$10))/1000*$U$5 -> 0 | V10: =K4*Q10*R10 -> 2201249.3
H11: Масса ВВ (конверт) | I11: кг. | J11: 0 | K11: =K10*D36 -> 0 | N11: Детонатор промежуточный "Сферит ДП" - 60/1,5 | O11: кг | P11: 0 | Q11: =K15/K4 -> 0.0061250872 | R11: 150 | S11: =IF(ISERR($P$11*$R$11)," ",($P$11*$R$11)) -> 0 | U11: =K4*Q11*R11 -> 27562.893 | V11: =K4*Q11*R11 -> 27562.893
H12: Кол-во п.м. | I12: п.м. | J12: =(J5+J6)*A10 -> 2312.318 | K12: =(K5+K6)*D10+K9 -> 2482.5985 | P12: =J17/1000 -> 0.085684292 | Q12: 0 | S12: =IF(ISERR($P$12*$R$12)," ",($P$12*$R$12)) -> 0 | T12: =IF(ISERR($Q$12*$R$12)," ",($Q$12*$R$12)) -> 0 | U12: =IF(ISERR($P$12*$R$12)," ",($P$12*$R$12)) -> 0 | V12: =IF(ISERR($Q$12*$R$12)," ",($Q$12*$R$12)) -> 0
